<?xml version="1.0"?>
<robot name="robot" xmlns:xacro="http://www.ros.org/wiki/xacro">

    <joint name="chassis_joint" type="fixed">
        <parent link="base_link" />
        <child link="chassis_link" />
        <origin xyz="-0.1 0 0" rpy="0 0 0" />
    </joint>

    <joint name="left_wheel_joint" type="continuous">
        <parent link="base_link" />
        <child link="left_wheel_link" />
        <origin xyz="0 0.175 0" rpy="${-pi/2} 0 0"/>
        <axis xyz="0 0 1" />
    </joint>

    <joint name="right_wheel_joint" type="continuous">
        <parent link="base_link" />
        <child link="right_wheel_link" />
        <origin xyz="0 -0.175 0" rpy="${pi/2} 0 0" />
        <axis xyz="0 0 -1" />
    </joint>

    <joint name="caster_wheel_joint" type="fixed">
        <parent link="chassis_link"/>
        <child link="caster_link" />
        <origin xyz="0.24 0 0" rpy="0 0 0" />
    </joint>

</robot>