<?xml version="1.0"?>
<robot name="diff_bot" xmlns:xacro="http://www.ros.org/wiki/xacro">
    <joint name="chassis_joint" type="fixed">
        <parent link="base_link" />
        <child link="chassis" />
        <origin xyz="0 0 0.017" rpy="0 0 0" />
    </joint>

    <joint name="right_wheel_joint" type="continuous">
        <parent link="chassis" />
        <child link="right_wheel" />
        <origin xyz="-0.067 -0.082 0.008" rpy="0 0 0" />
        <limits effort="10" velocity="10" />
        <axis xyz="0 1 0" />
    </joint>

    <joint name="left_wheel_joint" type="continuous">
        <parent link="chassis" />
        <child link="left_wheel" />
        <origin xyz="-0.067 0.082 0.008" rpy="0 0 ${pi}" />
        <limits effort="10" velocity="10" />
        <axis xyz="0 -1 0" />
    </joint>

    <joint name="lidar_joint" type="fixed">
        <parent link="chassis" />
        <child link="lidar" />
        <origin xyz="0 0 0.065" rpy="0 0 0" />
    </joint>
    
    <joint name="camera_joint" type="fixed">
        <parent link="chassis" />
        <child link="camera" />
        <origin xyz="0.1 0 0.02" rpy="0 0 0" />
    </joint>
</robot>