<?xml version="1.0"?>
<robot name="ultron" xmlns:xacro="http://www.ros.org/wiki/xacro">

    <joint name="chassis_joint" type="fixed">
        <parent link="base_link" />
        <child link="chassis_link" />
        <origin xyz="0 0 0.017" rpy="0 0 0" />
    </joint>

    <joint name="right_wheel_joint" type="continuous">
        <parent link="chassis_link" />
        <child link="right_wheel_link" />
        <origin xyz="-0.067 -0.089 0.008" rpy="0 0 0" />
        <axis xyz="0 1 0" />
    </joint>

    <joint name="left_wheel_joint" type="continuous">
        <parent link="chassis_link" />
        <child link="left_wheel_link" />
        <origin xyz="-0.067 0.089 0.008" rpy="0 0 0" />
        <axis xyz="0 1 0" />
    </joint>

    <joint name="lidar_joint" type="fixed">
        <parent link="chassis_link" />
        <child link="lidar_link" />
        <origin xyz="0 0 0.0775" rpy="0 0 0" />
    </joint>

</robot>